<robot
  name="mybot_description">
  <link
    name="base_link">
    <inertial>
      <origin
        xyz="0.00059823 -0.00070645 0.015343"
        rpy="0 0 0" />
      <mass
        value="0.31947" />
      <inertia
        ixx="0.00052125"
        ixy="1.1384E-07"
        ixz="-2.2716E-06"
        iyy="0.0005196"
        iyz="2.4232E-06"
        izz="0.00091204" />
    </inertial>
    <visual>
      <origin
        xyz="0 0 0"
        rpy="0 0 0" />
      <geometry>
        <mesh
          filename="package://mybot_description/meshes/base_link.STL" />
      </geometry>
      <material
        name="">
        <color
          rgba="0.79216 0.81961 0.93333 1" />
      </material>
    </visual>
    <collision>
      <origin
        xyz="0 0 0"
        rpy="0 0 0" />
      <geometry>
        <mesh
          filename="package://mybot_description/meshes/base_link.STL" />
      </geometry>
    </collision>
  </link>
  <link
    name="link0">
    <inertial>
      <origin
        xyz="0.0015406 0.0013202 0.030331"
        rpy="0 0 0" />
      <mass
        value="0.053848" />
      <inertia
        ixx="1.7354E-05"
        ixy="4.9601E-07"
        ixz="-1.0513E-06"
        iyy="1.7196E-05"
        iyz="-9.0113E-07"
        izz="1.3819E-05" />
    </inertial>
    <visual>
      <origin
        xyz="0 0 0"
        rpy="0 0 0" />
      <geometry>
        <mesh
          filename="package://mybot_description/meshes/link0.STL" />
      </geometry>
      <material
        name="">
        <color
          rgba="0.79216 0.81961 0.93333 1" />
      </material>
    </visual>
    <collision>
      <origin
        xyz="0 0 0"
        rpy="0 0 0" />
      <geometry>
        <mesh
          filename="package://mybot_description/meshes/link0.STL" />
      </geometry>
    </collision>
  </link>
  <joint
    name="joint0"
    type="revolute">
    <origin
      xyz="0 0 0.032517"
      rpy="-1.3289E-17 -1.2317E-16 -1.1102E-14" />
    <parent
      link="base_link" />
    <child
      link="link0" />
    <axis
      xyz="0 0 1" />
    <limit
      lower="-3.14"
      upper="3.14"
      effort="1"
      velocity="0.5" />
  </joint>
  <link
    name="link1">
    <inertial>
      <origin
        xyz="0.023455 -1.7325E-08 0.044232"
        rpy="0 0 0" />
      <mass
        value="0.066865" />
      <inertia
        ixx="5.3591E-05"
        ixy="-9.3675E-12"
        ixz="2.5595E-06"
        iyy="6.2629E-05"
        iyz="1.3043E-10"
        izz="2.7389E-05" />
    </inertial>
    <visual>
      <origin
        xyz="0 0 0"
        rpy="0 0 0" />
      <geometry>
        <mesh
          filename="package://mybot_description/meshes/link1.STL" />
      </geometry>
      <material
        name="">
        <color
          rgba="0.79216 0.81961 0.93333 1" />
      </material>
    </visual>
    <collision>
      <origin
        xyz="0 0 0"
        rpy="0 0 0" />
      <geometry>
        <mesh
          filename="package://mybot_description/meshes/link1.STL" />
      </geometry>
    </collision>
  </link>
  <joint
    name="joint1"
    type="revolute">
    <origin
      xyz="0.019303 0.016509 0.048983"
      rpy="-2.7272E-16 -4.6161E-16 -2.434" />
    <parent
      link="link0" />
    <child
      link="link1" />
    <axis
      xyz="-1 0 0" />
    <limit
      lower="-1.05"
      upper="1.05"
      effort="1"
      velocity="0.5" />
  </joint>
  <link
    name="link2">
    <inertial>
      <origin
        xyz="0.023455 -7.9525E-09 0.044232"
        rpy="0 0 0" />
      <mass
        value="0.066865" />
      <inertia
        ixx="5.3591E-05"
        ixy="-3.5917E-13"
        ixz="2.5596E-06"
        iyy="6.2629E-05"
        iyz="1.4247E-10"
        izz="2.7389E-05" />
    </inertial>
    <visual>
      <origin
        xyz="0 0 0"
        rpy="0 0 0" />
      <geometry>
        <mesh
          filename="package://mybot_description/meshes/link2.STL" />
      </geometry>
      <material
        name="">
        <color
          rgba="0.79216 0.81961 0.93333 1" />
      </material>
    </visual>
    <collision>
      <origin
        xyz="0 0 0"
        rpy="0 0 0" />
      <geometry>
        <mesh
          filename="package://mybot_description/meshes/link2.STL" />
      </geometry>
    </collision>
  </link>
  <joint
    name="joint2"
    type="revolute">
    <origin
      xyz="-0.0004 0 0.0745"
      rpy="2.5246E-18 1.9213E-15 3.8858E-16" />
    <parent
      link="link1" />
    <child
      link="link2" />
    <axis
      xyz="-1 0 0" />
    <limit
      lower="-1.05"
      upper="1.05"
      effort="1"
      velocity="0.5" />
  </joint>
  <link
    name="link3">
    <inertial>
      <origin
        xyz="0.023455 -1.7325E-08 0.044232"
        rpy="0 0 0" />
      <mass
        value="0.066865" />
      <inertia
        ixx="5.3591E-05"
        ixy="-9.3675E-12"
        ixz="2.5595E-06"
        iyy="6.2629E-05"
        iyz="1.3043E-10"
        izz="2.7389E-05" />
    </inertial>
    <visual>
      <origin
        xyz="0 0 0"
        rpy="0 0 0" />
      <geometry>
        <mesh
          filename="package://mybot_description/meshes/link3.STL" />
      </geometry>
      <material
        name="">
        <color
          rgba="0.79216 0.81961 0.93333 1" />
      </material>
    </visual>
    <collision>
      <origin
        xyz="0 0 0"
        rpy="0 0 0" />
      <geometry>
        <mesh
          filename="package://mybot_description/meshes/link3.STL" />
      </geometry>
    </collision>
  </link>
  <joint
    name="joint3"
    type="revolute">
    <origin
      xyz="-0.0004 0 0.0745"
      rpy="1.8711E-17 -2.2428E-15 -5.5511E-16" />
    <parent
      link="link2" />
    <child
      link="link3" />
    <axis
      xyz="-1 0 0" />
    <limit
      lower="-1.05"
      upper="1.05"
      effort="1"
      velocity="0.5" />
  </joint>
  <link
    name="gripper">
    <inertial>
      <origin
        xyz="0.027134 -0.00019736 0.02219"
        rpy="0 0 0" />
      <mass
        value="0.041798" />
      <inertia
        ixx="1.9479E-05"
        ixy="-1.1068E-09"
        ixz="1.5196E-07"
        iyy="3.3475E-05"
        iyz="9.0738E-08"
        izz="2.3209E-05" />
    </inertial>
    <visual>
      <origin
        xyz="0 0 0"
        rpy="0 0 0" />
      <geometry>
        <mesh
          filename="package://mybot_description/meshes/gripper.STL" />
      </geometry>
      <material
        name="">
        <color
          rgba="1 1 1 1" />
      </material>
    </visual>
    <collision>
      <origin
        xyz="0 0 0"
        rpy="0 0 0" />
      <geometry>
        <mesh
          filename="package://mybot_description/meshes/gripper.STL" />
      </geometry>
    </collision>
  </link>
  <joint
    name="joint4"
    type="revolute">
    <origin
      xyz="-0.0014 0 0.0745"
      rpy="2.4063E-16 1.3381E-15 1.0547E-15" />
    <parent
      link="link3" />
    <child
      link="gripper" />
    <axis
      xyz="-1 0 0" />
    <limit
      lower="-1.05"
      upper="1.05"
      effort="1"
      velocity="0.5" />
  </joint>
</robot>